[2017/04/28 10:52:37][ERROR](wrapper.py:18) no data found for the key
[2017/04/28 10:52:37][ERROR](wrapper.py:19) Traceback (most recent call last):
  File "wrapper.py", line 16, in _wrapper
    return func(self, *args, **kwargs)
  File "wrapper.py", line 41, in active_orders
    return super().active_orders(**kwargs)
  File "C:\Users\dshir\Desktop\Pycharm\zaifbot\lib\site-packages\zaifapi\impl.py", line 231, in active_orders
    return self._execute_api(inspect.currentframe().f_code.co_name, schema_keys, kwargs)
  File "C:\Users\dshir\Desktop\Pycharm\zaifbot\lib\site-packages\zaifapi\impl.py", line 210, in _execute_api
    raise ZaifApiError(res['error'])
zaifapi.api_error.ZaifApiError: no data found for the key

[2017/04/28 10:53:08][ERROR](wrapper.py:18) no data found for the key
[2017/04/28 10:53:08][ERROR](wrapper.py:19) Traceback (most recent call last):
  File "wrapper.py", line 16, in _wrapper
    return func(self, *args, **kwargs)
  File "wrapper.py", line 41, in active_orders
    return super().active_orders(**kwargs)
  File "C:\Users\dshir\Desktop\Pycharm\zaifbot\lib\site-packages\zaifapi\impl.py", line 231, in active_orders
    return self._execute_api(inspect.currentframe().f_code.co_name, schema_keys, kwargs)
  File "C:\Users\dshir\Desktop\Pycharm\zaifbot\lib\site-packages\zaifapi\impl.py", line 210, in _execute_api
    raise ZaifApiError(res['error'])
zaifapi.api_error.ZaifApiError: no data found for the key

[2017/04/28 10:53:08][ERROR](wrapper.py:18) no data found for the key
[2017/04/28 10:53:08][ERROR](wrapper.py:19) Traceback (most recent call last):
  File "wrapper.py", line 16, in _wrapper
    return func(self, *args, **kwargs)
  File "wrapper.py", line 41, in active_orders
    return super().active_orders(**kwargs)
  File "C:\Users\dshir\Desktop\Pycharm\zaifbot\lib\site-packages\zaifapi\impl.py", line 231, in active_orders
    return self._execute_api(inspect.currentframe().f_code.co_name, schema_keys, kwargs)
  File "C:\Users\dshir\Desktop\Pycharm\zaifbot\lib\site-packages\zaifapi\impl.py", line 210, in _execute_api
    raise ZaifApiError(res['error'])
zaifapi.api_error.ZaifApiError: no data found for the key

[2017/04/28 10:53:08][ERROR](wrapper.py:18) no data found for the key
[2017/04/28 10:53:08][ERROR](wrapper.py:19) Traceback (most recent call last):
  File "wrapper.py", line 16, in _wrapper
    return func(self, *args, **kwargs)
  File "wrapper.py", line 41, in active_orders
    return super().active_orders(**kwargs)
  File "C:\Users\dshir\Desktop\Pycharm\zaifbot\lib\site-packages\zaifapi\impl.py", line 231, in active_orders
    return self._execute_api(inspect.currentframe().f_code.co_name, schema_keys, kwargs)
  File "C:\Users\dshir\Desktop\Pycharm\zaifbot\lib\site-packages\zaifapi\impl.py", line 210, in _execute_api
    raise ZaifApiError(res['error'])
zaifapi.api_error.ZaifApiError: no data found for the key

[2017/04/28 10:53:08][ERROR](wrapper.py:18) no data found for the key
[2017/04/28 10:53:08][ERROR](wrapper.py:19) Traceback (most recent call last):
  File "wrapper.py", line 16, in _wrapper
    return func(self, *args, **kwargs)
  File "wrapper.py", line 41, in active_orders
    return super().active_orders(**kwargs)
  File "C:\Users\dshir\Desktop\Pycharm\zaifbot\lib\site-packages\zaifapi\impl.py", line 231, in active_orders
    return self._execute_api(inspect.currentframe().f_code.co_name, schema_keys, kwargs)
  File "C:\Users\dshir\Desktop\Pycharm\zaifbot\lib\site-packages\zaifapi\impl.py", line 210, in _execute_api
    raise ZaifApiError(res['error'])
zaifapi.api_error.ZaifApiError: no data found for the key

[2017/04/28 10:53:08][ERROR](wrapper.py:18) no data found for the key
[2017/04/28 10:53:08][ERROR](wrapper.py:19) Traceback (most recent call last):
  File "wrapper.py", line 16, in _wrapper
    return func(self, *args, **kwargs)
  File "wrapper.py", line 41, in active_orders
    return super().active_orders(**kwargs)
  File "C:\Users\dshir\Desktop\Pycharm\zaifbot\lib\site-packages\zaifapi\impl.py", line 231, in active_orders
    return self._execute_api(inspect.currentframe().f_code.co_name, schema_keys, kwargs)
  File "C:\Users\dshir\Desktop\Pycharm\zaifbot\lib\site-packages\zaifapi\impl.py", line 210, in _execute_api
    raise ZaifApiError(res['error'])
zaifapi.api_error.ZaifApiError: no data found for the key

[2017/04/28 10:55:28][ERROR](wrapper.py:18) no data found for the key
[2017/04/28 10:55:28][ERROR](wrapper.py:19) Traceback (most recent call last):
  File "wrapper.py", line 16, in _wrapper
    return func(self, *args, **kwargs)
  File "wrapper.py", line 41, in active_orders
    return super().active_orders(**kwargs)
  File "C:\Users\dshir\Desktop\Pycharm\zaifbot\lib\site-packages\zaifapi\impl.py", line 231, in active_orders
    return self._execute_api(inspect.currentframe().f_code.co_name, schema_keys, kwargs)
  File "C:\Users\dshir\Desktop\Pycharm\zaifbot\lib\site-packages\zaifapi\impl.py", line 210, in _execute_api
    raise ZaifApiError(res['error'])
zaifapi.api_error.ZaifApiError: no data found for the key

[2017/04/28 10:55:50][ERROR](wrapper.py:18) no data found for the key
[2017/04/28 10:55:50][ERROR](wrapper.py:19) Traceback (most recent call last):
  File "wrapper.py", line 16, in _wrapper
    return func(self, *args, **kwargs)
  File "wrapper.py", line 41, in active_orders
    return super().active_orders(**kwargs)
  File "C:\Users\dshir\Desktop\Pycharm\zaifbot\lib\site-packages\zaifapi\impl.py", line 231, in active_orders
    return self._execute_api(inspect.currentframe().f_code.co_name, schema_keys, kwargs)
  File "C:\Users\dshir\Desktop\Pycharm\zaifbot\lib\site-packages\zaifapi\impl.py", line 210, in _execute_api
    raise ZaifApiError(res['error'])
zaifapi.api_error.ZaifApiError: no data found for the key

[2017/04/28 11:02:01][ERROR](wrapper.py:28) No active exception to reraise
[2017/04/28 11:02:01][ERROR](wrapper.py:29) Traceback (most recent call last):
  File "wrapper.py", line 16, in _wrapper
    return func(self, *args, **kwargs)
  File "wrapper.py", line 89, in last_price
    raise
RuntimeError: No active exception to reraise

[2017/04/28 11:02:06][ERROR](wrapper.py:28) No active exception to reraise
[2017/04/28 11:02:06][ERROR](wrapper.py:29) Traceback (most recent call last):
  File "wrapper.py", line 16, in _wrapper
    return func(self, *args, **kwargs)
  File "wrapper.py", line 89, in last_price
    raise
RuntimeError: No active exception to reraise

[2017/04/28 11:02:11][ERROR](wrapper.py:28) No active exception to reraise
[2017/04/28 11:02:11][ERROR](wrapper.py:29) Traceback (most recent call last):
  File "wrapper.py", line 16, in _wrapper
    return func(self, *args, **kwargs)
  File "wrapper.py", line 89, in last_price
    raise
RuntimeError: No active exception to reraise

[2017/04/28 11:02:16][ERROR](wrapper.py:28) No active exception to reraise
[2017/04/28 11:02:16][ERROR](wrapper.py:29) Traceback (most recent call last):
  File "wrapper.py", line 16, in _wrapper
    return func(self, *args, **kwargs)
  File "wrapper.py", line 89, in last_price
    raise
RuntimeError: No active exception to reraise

[2017/04/28 11:02:21][ERROR](wrapper.py:28) No active exception to reraise
[2017/04/28 11:02:21][ERROR](wrapper.py:29) Traceback (most recent call last):
  File "wrapper.py", line 16, in _wrapper
    return func(self, *args, **kwargs)
  File "wrapper.py", line 89, in last_price
    raise
RuntimeError: No active exception to reraise

